Traceback (most recent call last):
  File "C:\Users\Matt\.conda\envs\gdal\lib\runpy.py", line 196, in _run_module_as_main
    return _run_code(code, main_globals, None,
  File "C:\Users\Matt\.conda\envs\gdal\lib\runpy.py", line 86, in _run_code
    exec(code, run_globals)
  File "C:\Users\Matt\.conda\envs\gdal\Scripts\gdal_merge.exe\__main__.py", line 7, in <module>
  File "C:\Users\Matt\.conda\envs\gdal\lib\site-packages\osgeo_utils\gdal_merge.py", line 323, in main
    argv = gdal.GeneralCmdLineProcessor(argv)
  File "C:\Users\Matt\.conda\envs\gdal\lib\site-packages\osgeo\gdal.py", line 4596, in GeneralCmdLineProcessor
    return _gdal.GeneralCmdLineProcessor(*args)
TypeError: not a sequence
